2022-11-16 10:12:52,402 INFO    StreamThr :15544 [internal.py:wandb_internal():88] W&B internal server running at pid: 15544, started at: 2022-11-16 10:12:52.386664
2022-11-16 10:12:52,402 DEBUG   HandlerThread:15544 [handler.py:handle_request():139] handle_request: status
2022-11-16 10:12:52,402 DEBUG   SenderThread:15544 [sender.py:send_request():317] send_request: status
2022-11-16 10:12:52,402 DEBUG   SenderThread:15544 [sender.py:send():303] send: header
2022-11-16 10:12:52,402 INFO    WriterThread:15544 [datastore.py:open_for_write():75] open: D:\ATLOP-main\wandb\run-20221116_101245-1yj79jbc\run-1yj79jbc.wandb
2022-11-16 10:12:52,402 DEBUG   SenderThread:15544 [sender.py:send():303] send: run
2022-11-16 10:12:55,891 ERROR   SenderThread:15544 [retry.py:__call__():154] Retry attempt failed:
Traceback (most recent call last):
  File "C:\Users\pc\anaconda3\lib\site-packages\urllib3\connectionpool.py", line 700, in urlopen
    self._prepare_proxy(conn)
  File "C:\Users\pc\anaconda3\lib\site-packages\urllib3\connectionpool.py", line 996, in _prepare_proxy
    conn.connect()
  File "C:\Users\pc\anaconda3\lib\site-packages\urllib3\connection.py", line 364, in connect
    self.sock = conn = self._connect_tls_proxy(hostname, conn)
  File "C:\Users\pc\anaconda3\lib\site-packages\urllib3\connection.py", line 499, in _connect_tls_proxy
    socket = ssl_wrap_socket(
  File "C:\Users\pc\anaconda3\lib\site-packages\urllib3\util\ssl_.py", line 453, in ssl_wrap_socket
    ssl_sock = _ssl_wrap_socket_impl(sock, context, tls_in_tls)
  File "C:\Users\pc\anaconda3\lib\site-packages\urllib3\util\ssl_.py", line 495, in _ssl_wrap_socket_impl
    return ssl_context.wrap_socket(sock)
  File "C:\Users\pc\anaconda3\lib\ssl.py", line 500, in wrap_socket
    return self.sslsocket_class._create(
  File "C:\Users\pc\anaconda3\lib\ssl.py", line 1040, in _create
    self.do_handshake()
  File "C:\Users\pc\anaconda3\lib\ssl.py", line 1309, in do_handshake
    self._sslobj.do_handshake()
ssl.SSLEOFError: EOF occurred in violation of protocol (_ssl.c:1129)

During handling of the above exception, another exception occurred:

Traceback (most recent call last):
  File "C:\Users\pc\anaconda3\lib\site-packages\requests\adapters.py", line 489, in send
    resp = conn.urlopen(
  File "C:\Users\pc\anaconda3\lib\site-packages\urllib3\connectionpool.py", line 787, in urlopen
    retries = retries.increment(
  File "C:\Users\pc\anaconda3\lib\site-packages\urllib3\util\retry.py", line 592, in increment
    raise MaxRetryError(_pool, url, error or ResponseError(cause))
urllib3.exceptions.MaxRetryError: HTTPSConnectionPool(host='api.wandb.ai', port=443): Max retries exceeded with url: /graphql (Caused by SSLError(SSLEOFError(8, 'EOF occurred in violation of protocol (_ssl.c:1129)')))

During handling of the above exception, another exception occurred:

Traceback (most recent call last):
  File "C:\Users\pc\anaconda3\lib\site-packages\wandb\sdk\lib\retry.py", line 113, in __call__
    result = self._call_fn(*args, **kwargs)
  File "C:\Users\pc\anaconda3\lib\site-packages\wandb\sdk\internal\internal_api.py", line 210, in execute
    return self.client.execute(*args, **kwargs)  # type: ignore
  File "C:\Users\pc\anaconda3\lib\site-packages\wandb\vendor\gql-0.2.0\wandb_gql\client.py", line 52, in execute
    result = self._get_result(document, *args, **kwargs)
  File "C:\Users\pc\anaconda3\lib\site-packages\wandb\vendor\gql-0.2.0\wandb_gql\client.py", line 60, in _get_result
    return self.transport.execute(document, *args, **kwargs)
  File "C:\Users\pc\anaconda3\lib\site-packages\wandb\vendor\gql-0.2.0\wandb_gql\transport\requests.py", line 38, in execute
    request = requests.post(self.url, **post_args)
  File "C:\Users\pc\anaconda3\lib\site-packages\requests\api.py", line 115, in post
    return request("post", url, data=data, json=json, **kwargs)
  File "C:\Users\pc\anaconda3\lib\site-packages\requests\api.py", line 59, in request
    return session.request(method=method, url=url, **kwargs)
  File "C:\Users\pc\anaconda3\lib\site-packages\requests\sessions.py", line 587, in request
    resp = self.send(prep, **send_kwargs)
  File "C:\Users\pc\anaconda3\lib\site-packages\requests\sessions.py", line 701, in send
    r = adapter.send(request, **kwargs)
  File "C:\Users\pc\anaconda3\lib\site-packages\requests\adapters.py", line 563, in send
    raise SSLError(e, request=request)
requests.exceptions.SSLError: HTTPSConnectionPool(host='api.wandb.ai', port=443): Max retries exceeded with url: /graphql (Caused by SSLError(SSLEOFError(8, 'EOF occurred in violation of protocol (_ssl.c:1129)')))
2022-11-16 10:12:57,409 DEBUG   HandlerThread:15544 [handler.py:handle_request():139] handle_request: keepalive
2022-11-16 10:13:02,434 DEBUG   HandlerThread:15544 [handler.py:handle_request():139] handle_request: keepalive
2022-11-16 10:13:07,459 DEBUG   HandlerThread:15544 [handler.py:handle_request():139] handle_request: keepalive
2022-11-16 10:13:12,493 DEBUG   HandlerThread:15544 [handler.py:handle_request():139] handle_request: keepalive
2022-11-16 10:13:17,518 DEBUG   HandlerThread:15544 [handler.py:handle_request():139] handle_request: keepalive
2022-11-16 10:13:22,549 DEBUG   HandlerThread:15544 [handler.py:handle_request():139] handle_request: keepalive
2022-11-16 10:13:27,588 DEBUG   HandlerThread:15544 [handler.py:handle_request():139] handle_request: keepalive
2022-11-16 10:13:32,605 DEBUG   HandlerThread:15544 [handler.py:handle_request():139] handle_request: keepalive
2022-11-16 10:13:37,647 DEBUG   HandlerThread:15544 [handler.py:handle_request():139] handle_request: keepalive
2022-11-16 10:13:41,705 WARNING StreamThr :15544 [internal.py:is_dead():385] Internal process exiting, parent pid 24088 disappeared
2022-11-16 10:13:41,705 ERROR   StreamThr :15544 [internal.py:wandb_internal():147] Internal process shutdown.
2022-11-16 10:13:41,720 INFO    WriterThread:15544 [datastore.py:close():279] close: D:\ATLOP-main\wandb\run-20221116_101245-1yj79jbc\run-1yj79jbc.wandb
2022-11-16 10:13:42,681 INFO    HandlerThread:15544 [handler.py:finish():814] shutting down handler
2022-11-16 10:13:42,696 INFO    MainThread:15544 [internal.py:handle_exit():78] Internal process exited
2022-11-16 10:13:42,696 WARNING MsgRouterThr:15544 [router.py:message_loop():74] EOFError seen in message_loop
